Workbook

Sheet Nota Explicativa
B2: Nota Explicativa — Como Funciona Esta Planilha
B4: 1. Objetivo
B5: Estimar a economia decorrente da equiparação das idades mínimas da aposentadoria rural por idade às da clientela urbana (de 60 anos para 65, homens; de 55 para 62, mulheres), em valores nominais e reais (R$ de 2026), até 2060. Dois desenhos de transição são calculados em abas distintas, ambas igualmente válidas: "Transição 9 H e 13 M Anos" (acréscimo de 1 ano a cada 2 anos a partir de 2027: 9 anos para os homens e 13 para as mulheres) e "Transição Uniforme 10 Anos" (acréscimo gradual, em meses, aplicado a cada janeiro, com a mesma duração de 10 anos para ambos os sexos). Cada aba traz também o cenário sem transição (idade proposta exigida desde 2027). A duração de cada transição consta da premissa 6 (seção 6).
B6: Refinamento em relação à versão anterior: na regra vigente (cenário de referência), a concessão passa a ocorrer, por padrão, na idade média efetiva (Ī, média 2020–2025 por sexo), e não na idade mínima vigente. O quadro "Cenário de Referência" de cada aba permite alternar entre as duas.
B8: 2. Estrutura
B9: As duas abas de cálculo, "Transição 9 H e 13 M Anos" e "Transição Uniforme 10 Anos", têm a mesma estrutura: tabela principal (B2:W55); quadro "Cenário de Referência" (Y5:AA9) e resultado acumulado (AC5:AE8); parâmetros (Y12:AA20); idade média efetiva (AG5:AI14); e, abaixo da tabela principal, a memória de cálculo das colunas M e S (linha 59 em diante, agrupada: use o [+] para expandir). Na aba "Transição Uniforme 10 Anos", a memória de cálculo inclui ainda a tabela de acréscimo exigido por ano e o cálculo por mês de entrada, e o quadro AC11:AE16 compara os resultados das duas abas.
B10: Os dados comuns (fluxo de concessões, salário mínimo e inflação, idades médias, idades mínimas, início da vigência e pagamentos por ano) são digitados uma única vez, na aba "Transição 9 H e 13 M Anos", e vinculados por fórmula à aba "Transição Uniforme 10 Anos". São próprios de cada aba o seletor do cenário de referência (Z6) e a regra de transição: o intervalo entre acréscimos (Z19) na aba "Transição 9 H e 13 M Anos" e a duração da transição (Z19) na aba "Transição Uniforme 10 Anos". A memória de cálculo contém fórmulas automáticas e não requer edição. Esta aba é apenas explicativa: nenhuma fórmula depende dela.
B12: 3. Passo a passo do cálculo
B13: 1) Fluxo de concessões (colunas C a H). Histórico do AEPS até 2024; a partir de 2025, População × Constância de Incidência (média 2020–2024). Cada ano forma uma coorte: os segurados que atingem a idade mínima vigente (60 anos, homens; 55, mulheres) naquele ano.
B14: 2) Atraso da concessão na regra vigente (Z16:AA17, em cada aba). A diferença entre Ī (60,735 anos, homens; 56,330, mulheres) e a idade mínima vigente, em meses inteiros, é o parâmetro Δ: 9 meses (homens) e 16 meses (mulheres) com o seletor em "Idade média efetiva"; com o seletor em "Idade mínima vigente", Δ = 0.
B15: 3) Idade mínima exigida em cada ano. Em ambas as abas, o cenário sem transição exige a idade proposta desde 2027. Nos cenários com transição, a aba "Transição 9 H e 13 M Anos" eleva a idade mínima em 1 ano a cada Z19 anos (padrão: 2), a partir de 2027 (Z18), até 65 anos (homens) e 62 anos (mulheres), o que leva 9 e 13 anos, respectivamente. Já a aba "Transição Uniforme 10 Anos" eleva a idade mínima em meses a cada janeiro, a partir de 2027, ao longo de Z19 anos (padrão: 10), para ambos os sexos: o acréscimo no ano é igual a 12 × (idade proposta − idade vigente) × n ÷ duração, com n = anos desde o início da vigência (limitado à duração), expresso em meses. Com 10 anos, os homens têm +6 meses por ano e as mulheres +8,4 meses por ano, o que exige arredondamento ao mês inteiro, tratado no parágrafo seguinte.
B16: Arredondamento do acréscimo (aba "Transição Uniforme 10 Anos"). O arredondamento citado no item 3 decorre de a idade exigida variar apenas em meses inteiros e de o acréscimo anual das mulheres não ser inteiro: 84 meses (de 55 para 62 anos) em 10 anos equivalem a 8,4 meses por ano. Por essa razão, para cada ano de vigência n, a planilha calcula o acréscimo acumulado exato (84 × n ÷ 10) e o arredonda ao mês inteiro mais próximo, pela fórmula ARRED[12 × (62 − 55) × n ÷ 10; 0]. Em meses acumulados (exato → arredondado), o resultado é: n = 1: 8,4 → 8; 2: 16,8 → 17; 3: 25,2 → 25; 4: 33,6 → 34; 5: 42,0 → 42; 6: 50,4 → 50; 7: 58,8 → 59; 8: 67,2 → 67; 9: 75,6 → 76; 10: 84,0 → 84. Com isso, os saltos de cada janeiro alternam entre 8 e 9 meses (8, 9, 8, 9, 8, 8, 9, 8, 9, 8). Como o arredondamento incide sobre o acumulado, e não sobre cada salto, o desvio em relação ao percurso exato nunca excede 0,5 mês e não se acumula: em 2036, último ano da transição, o acréscimo é exatamente 84 meses e as mulheres chegam a 62 anos. Para os homens, ao contrário, não há arredondamento, pois 60 meses em 10 anos equivalem exatamente a 6 meses por ano. Com outras durações (Z19), o mesmo procedimento se aplica a ambos os sexos.
... B44: 14) Desenho do acréscimo na aba "Transição Uniforme 10 Anos": o acréscimo em meses, em vez de degraus anuais, evita que a idade exigida suba 1 ano por ano e acompanhe o envelhecimento das coortes, o que impediria a concessão até o fim da transição; há precedente na EC nº 103/2019 (art. 16, § 1º, e art. 18, § 1º, com 6 meses por ano). A escolha do desenho é decisão de política.

Sheet Transição 9 H e 13 M Anos
B2: Análise da Economia Estimada com a Proposta de Aumento da Idade Mínima para Aposentadoria Rural
B3: Fluxo de Concessões e Parâmetros Econômicos | L3: Sem Transição | R3: ="Transição de "&(($Z$15-$Z$14-1)*$Z$19+1)&" anos (H) e "&(($AA$15-$AA$14-1)*$Z$19+1)&" anos (M)" -> Transição de 9 anos (H) e 13 anos (M)
B4: Ano | C4: Aposentadorias Rurais por Idade Concedidas para o Sexo Masculino | D4: População de Homens com 60 anos | E4: Constância de Incidência (Homens) | F4: Aposentadorias Rurais por Idade Concedidas para o Sexo Feminino | G4: População de Mulheres com 55 anos | H4: Constância de Incidência (Mulheres) | I4: Salário Mínimo | J4: Inflação (INPC) | K4: Inflação Acumulada | L4: Idade Mínima | M4: Emissões Adiadas | N4: Economia Nominal Projetada | O4: Economia Nominal Projetada Acumulada | P4: Economia Real Projetada | Q4: Economia Real Projetada Acumulada | R4: Idade Mínima | S4: Emissões Adiadas | T4: Economia Nominal Projetada | U4: Economia Nominal Projetada Acumulada | V4: Economia Real Projetada | W4: Economia Real Projetada Acumulada
B5: 2010 | C5: 147356 | D5: 684213 | E5: =C5/D5 -> 0.21536568 | F5: 199978 | G5: 958517 | H5: =F5/G5 -> 0.20863271 | I5: 510 | J5: 0.064652 | K5: - | L5: =IF($B5<$Z$18,$AA$14&"M / "&$Z$14&"H",$AA$15&"M / "&$Z$15&"H") -> 55M / 60H | M5: - | N5: 0 | O5: 0 | P5: 0 | Q5: 0 | R5: =IF($B5<$Z$18,$AA$14&"M / "&$Z$14&"H",MIN($AA$15,$AA$14+1+INT(($B5-$Z$18)/$Z$19))&"M / "&MIN($Z$15,$Z$14+1+INT(($B5-$Z$18)/$Z$19))&"H") -> 55M / 60H | S5: - | T5: 0 | U5: 0 | V5: 0 | W5: 0 | Y5: Cenário de Referência — Idade de Concessão na Regra Vigente | AC5: Resultado do Cenário Selecionado | AG5: Idade Média Efetiva na DIB (Rural)
B6: 2011 | C6: 141310 | D6: 709218 | E6: =C6/D6 -> 0.19924762 | F6: 201742 | G6: 991806 | H6: =F6/G6 -> 0.20340873 | I6: 540 | J6: 0.060799 | K6: - | L6: =IF($B6<$Z$18,$AA$14&"M / "&$Z$14&"H",$AA$15&"M / "&$Z$15&"H") -> 55M / 60H | M6: - | N6: 0 | O6: 0 | P6: 0 | Q6: 0 | R6: =IF($B6<$Z$18,$AA$14&"M / "&$Z$14&"H",MIN($AA$15,$AA$14+1+INT(($B6-$Z$18)/$Z$19))&"M / "&MIN($Z$15,$Z$14+1+INT(($B6-$Z$18)/$Z$19))&"H") -> 55M / 60H | S6: - | T6: 0 | U6: 0 | V6: 0 | W6: 0 | Y6: Idade de concessão adotada (selecionar na lista): | Z6: Idade média efetiva | AC6: Economia Real Acumulada | AD6: Até 2030 | AE6: Até 2060 | AG6: Ano | AH6: Homens | AI6: Mulheres
B7: 2012 | C7: 148810 | D7: 734954 | E7: =C7/D7 -> 0.20247526 | F7: 203190 | G7: 1024678 | H7: =F7/G7 -> 0.19829644 | I7: 622 | J7: 0.061978 | K7: - | L7: =IF($B7<$Z$18,$AA$14&"M / "&$Z$14&"H",$AA$15&"M / "&$Z$15&"H") -> 55M / 60H | M7: - | N7: 0 | O7: 0 | P7: 0 | Q7: 0 | R7: =IF($B7<$Z$18,$AA$14&"M / "&$Z$14&"H",MIN($AA$15,$AA$14+1+INT(($B7-$Z$18)/$Z$19))&"M / "&MIN($Z$15,$Z$14+1+INT(($B7-$Z$18)/$Z$19))&"H") -> 55M / 60H | S7: - | T7: 0 | U7: 0 | V7: 0 | W7: 0 | Y7: Idade média efetiva: concessão aos Ī anos, em média (Δ meses após a idade mínima vigente). | AC7: Sem Transição | AD7: =Q25 -> 4.0476722e+10 | AE7: =Q55 -> 2.1230628e+12 | AG7: 2020 | AH7: 60.56 | AI7: 56.08
B8: 2013 | C8: 148885 | D8: 761573 | E8: =C8/D8 -> 0.19549669 | F8: 209735 | G8: 1057683 | H8: =F8/G8 -> 0.19829665 | I8: 678 | J8: 0.055627 | K8: - | L8: =IF($B8<$Z$18,$AA$14&"M / "&$Z$14&"H",$AA$15&"M / "&$Z$15&"H") -> 55M / 60H | M8: - | N8: 0 | O8: 0 | P8: 0 | Q8: 0 | R8: =IF($B8<$Z$18,$AA$14&"M / "&$Z$14&"H",MIN($AA$15,$AA$14+1+INT(($B8-$Z$18)/$Z$19))&"M / "&MIN($Z$15,$Z$14+1+INT(($B8-$Z$18)/$Z$19))&"H") -> 55M / 60H | S8: - | T8: 0 | U8: 0 | V8: 0 | W8: 0 | Y8: Idade mínima vigente: concessão exatamente aos 60 (H) e 55 (M) anos (premissa original). | AC8: ="Transição de "&(($Z$15-$Z$14-1)*$Z$19+1)&" anos (H) e "&(($AA$15-$AA$14-1)*$Z$19+1)&" anos (M)" -> Transição de 9 anos (H) e 13 anos (M) | AD8: =W25 -> 1.5394883e+10 | AE8: =W55 -> 1.9674513e+12 | AG8: 2021 | AH8: 60.74 | AI8: 56.24
B9: 2014 | C9: 148068 | D9: 789185 | E9: =C9/D9 -> 0.18762141 | F9: 189793 | G9: 1090856 | H9: =F9/G9 -> 0.17398538 | I9: 724 | J9: 0.062283 | K9: - | L9: =IF($B9<$Z$18,$AA$14&"M / "&$Z$14&"H",$AA$15&"M / "&$Z$15&"H") -> 55M / 60H | M9: - | N9: 0 | O9: 0 | P9: 0 | Q9: 0 | R9: =IF($B9<$Z$18,$AA$14&"M / "&$Z$14&"H",MIN($AA$15,$AA$14+1+INT(($B9-$Z$18)/$Z$19))&"M / "&MIN($Z$15,$Z$14+1+INT(($B9-$Z$18)/$Z$19))&"H") -> 55M / 60H | S9: - | T9: 0 | U9: 0 | V9: 0 | W9: 0 | Y9: Observação: define o ponto de partida (Δ) nos cenários sem e com transição. | AC9: =IF($C$108="OK","R$ bi deflacionados; atualizam com o seletor ao lado.","ATENÇÃO: ampliar as colunas k da memória de cálculo.") -> R$ bi deflacionados; atualizam com o seletor ao lado. | AG9: 2022 | AH9: 60.78 | AI9: 56.31
B10: 2015 | C10: 123166 | D10: 817332 | E10: =C10/D10 -> 0.15069274 | F10: 163510 | G10: 1123521 | H10: =F10/G10 -> 0.14553355 | I10: 788 | J10: 0.112762 | K10: - | L10: =IF($B10<$Z$18,$AA$14&"M / "&$Z$14&"H",$AA$15&"M / "&$Z$15&"H") -> 55M / 60H | M10: - | N10: 0 | O10: 0 | P10: 0 | Q10: 0 | R10: =IF($B10<$Z$18,$AA$14&"M / "&$Z$14&"H",MIN($AA$15,$AA$14+1+INT(($B10-$Z$18)/$Z$19))&"M / "&MIN($Z$15,$Z$14+1+INT(($B10-$Z$18)/$Z$19))&"H") -> 55M / 60H | S10: - | T10: 0 | U10: 0 | V10: 0 | W10: 0 | AG10: 2023 | AH10: 60.82 | AI10: 56.48
B11: 2016 | C11: 137321 | D11: 845348 | E11: =C11/D11 -> 0.16244316 | F11: 168089 | G11: 1155913 | H11: =F11/G11 -> 0.14541665 | I11: 880 | J11: 0.0658 | K11: - | L11: =IF($B11<$Z$18,$AA$14&"M / "&$Z$14&"H",$AA$15&"M / "&$Z$15&"H") -> 55M / 60H | M11: - | N11: 0 | O11: 0 | P11: 0 | Q11: 0 | R11: =IF($B11<$Z$18,$AA$14&"M / "&$Z$14&"H",MIN($AA$15,$AA$14+1+INT(($B11-$Z$18)/$Z$19))&"M / "&MIN($Z$15,$Z$14+1+INT(($B11-$Z$18)/$Z$19))&"H") -> 55M / 60H | S11: - | T11: 0 | U11: 0 | V11: 0 | W11: 0 | AG11: 2024 | AH11: 60.79 | AI11: 56.58
B12: 2017 | C12: 143953 | D12: 872932 | E12: =C12/D12 -> 0.16490746 | F12: 180043 | G12: 1186329 | H12: =F12/G12 -> 0.15176481 | I12: 937 | J12: 0.020669 | K12: - | L12: =IF($B12<$Z$18,$AA$14&"M / "&$Z$14&"H",$AA$15&"M / "&$Z$15&"H") -> 55M / 60H | M12: - | N12: 0 | O12: 0 | P12: 0 | Q12: 0 | R12: =IF($B12<$Z$18,$AA$14&"M / "&$Z$14&"H",MIN($AA$15,$AA$14+1+INT(($B12-$Z$18)/$Z$19))&"M / "&MIN($Z$15,$Z$14+1+INT(($B12-$Z$18)/$Z$19))&"H") -> 55M / 60H | S12: - | T12: 0 | U12: 0 | V12: 0 | W12: 0 | Y12: Parâmetros de Regra e de Cálculo | AG12: 2025 | AH12: 60.72 | AI12: 56.29
B13: 2018 | C13: 128360 | D13: 900259 | E13: =C13/D13 -> 0.14258119 | F13: 166897 | G13: 1211645 | H13: =F13/G13 -> 0.13774414 | I13: 954 | J13: 0.03434 | K13: - | L13: =IF($B13<$Z$18,$AA$14&"M / "&$Z$14&"H",$AA$15&"M / "&$Z$15&"H") -> 55M / 60H | M13: - | N13: 0 | O13: 0 | P13: 0 | Q13: 0 | R13: =IF($B13<$Z$18,$AA$14&"M / "&$Z$14&"H",MIN($AA$15,$AA$14+1+INT(($B13-$Z$18)/$Z$19))&"M / "&MIN($Z$15,$Z$14+1+INT(($B13-$Z$18)/$Z$19))&"H") -> 55M / 60H | S13: - | T13: 0 | U13: 0 | V13: 0 | W13: 0 | Y13: Parâmetro | Z13: Homens | AA13: Mulheres | AG13: Média 2020–2025 | AH13: =AVERAGE(AH7:AH12) -> 60.735 | AI13: =AVERAGE(AI7:AI12) -> 56.33
B14: 2019 | C14: 112392 | D14: 927304 | E14: =C14/D14 -> 0.12120297 | F14: 146999 | G14: 1238650 | H14: =F14/G14 -> 0.11867679 | I14: 998 | J14: 0.044816 | K14: - | L14: =IF($B14<$Z$18,$AA$14&"M / "&$Z$14&"H",$AA$15&"M / "&$Z$15&"H") -> 55M / 60H | M14: - | N14: 0 | O14: 0 | P14: 0 | Q14: 0 | R14: =IF($B14<$Z$18,$AA$14&"M / "&$Z$14&"H",MIN($AA$15,$AA$14+1+INT(($B14-$Z$18)/$Z$19))&"M / "&MIN($Z$15,$Z$14+1+INT(($B14-$Z$18)/$Z$19))&"H") -> 55M / 60H | S14: - | T14: 0 | U14: 0 | V14: 0 | W14: 0 | Y14: Idade mínima vigente (anos) | Z14: 60 | AA14: 55 | AG14: Projeção 2026–2060 | AH14: =AH13 -> 60.735 | AI14: =AI13 -> 56.33
B15: 2020 | C15: 125151 | D15: 952510 | E15: =C15/D15 -> 0.13139075 | F15: 154416 | G15: 1259472 | H15: =F15/G15 -> 0.12260376 | I15: 1045 | J15: 0.054473 | K15: - | L15: =IF($B15<$Z$18,$AA$14&"M / "&$Z$14&"H",$AA$15&"M / "&$Z$15&"H") -> 55M / 60H | M15: - | N15: 0 | O15: 0 | P15: 0 | Q15: 0 | R15: =IF($B15<$Z$18,$AA$14&"M / "&$Z$14&"H",MIN($AA$15,$AA$14+1+INT(($B15-$Z$18)/$Z$19))&"M / "&MIN($Z$15,$Z$14+1+INT(($B15-$Z$18)/$Z$19))&"H") -> 55M / 60H | S15: - | T15: 0 | U15: 0 | V15: 0 | W15: 0 | Y15: Idade mínima proposta — equiparada à urbana (anos) | Z15: 65 | AA15: 62 | AG15: Observação: idade média na data de início do benefício (DIB) das aposentadorias por idade rurais concedidas em cada ano. A média simples 2020–2025 é mantida constante até 2060 e alimenta Ī (Z16:AA16).
B16: 2021 | C16: 144418 | D16: 974702 | E16: =C16/D16 -> 0.14816631 | F16: 177797 | G16: 1271298 | H16: =F16/G16 -> 0.1398547 | I16: 1100 | J16: 0.101602 | K16: - | L16: =IF($B16<$Z$18,$AA$14&"M / "&$Z$14&"H",$AA$15&"M / "&$Z$15&"H") -> 55M / 60H | M16: - | N16: 0 | O16: 0 | P16: 0 | Q16: 0 | R16: =IF($B16<$Z$18,$AA$14&"M / "&$Z$14&"H",MIN($AA$15,$AA$14+1+INT(($B16-$Z$18)/$Z$19))&"M / "&MIN($Z$15,$Z$14+1+INT(($B16-$Z$18)/$Z$19))&"H") -> 55M / 60H | S16: - | T16: 0 | U16: 0 | V16: 0 | W16: 0 | Y16: Idade média efetiva de concessão — Ī (anos) | Z16: =AH14 -> 60.735 | AA16: =AI14 -> 56.33 | AG16: Fonte: base Concedidos (SUIBE/INSS), espécie 41. Por ser valor pontual, não captura a dispersão das idades de concessão (premissa 9 da Nota Explicativa).
B17: 2022 | C17: 181243 | D17: 996419 | E17: =C17/D17 -> 0.18189436 | F17: 219393 | G17: 1278635 | H17: =F17/G17 -> 0.17158376 | I17: 1212 | J17: 0.059324 | K17: - | L17: =IF($B17<$Z$18,$AA$14&"M / "&$Z$14&"H",$AA$15&"M / "&$Z$15&"H") -> 55M / 60H | M17: - | N17: 0 | O17: 0 | P17: 0 | Q17: 0 | R17: =IF($B17<$Z$18,$AA$14&"M / "&$Z$14&"H",MIN($AA$15,$AA$14+1+INT(($B17-$Z$18)/$Z$19))&"M / "&MIN($Z$15,$Z$14+1+INT(($B17-$Z$18)/$Z$19))&"H") -> 55M / 60H | S17: - | T17: 0 | U17: 0 | V17: 0 | W17: 0 | Y17: Defasagem da concessão na regra vigente — Δ (meses) | Z17: =IF($Z$6="Idade média efetiva",ROUND(12*(Z16-Z14),0),0) -> 9 | AA17: =IF($Z$6="Idade média efetiva",ROUND(12*(AA16-AA14),0),0) -> 16
B18: 2023 | C18: 198543 | D18: 1018596 | E18: =C18/D18 -> 0.1949183 | F18: 240257 | G18: 1286407 | H18: =F18/G18 -> 0.18676593 | I18: 1320 | J18: 0.03707 | K18: - | L18: =IF($B18<$Z$18,$AA$14&"M / "&$Z$14&"H",$AA$15&"M / "&$Z$15&"H") -> 55M / 60H | M18: - | N18: 0 | O18: 0 | P18: 0 | Q18: 0 | R18: =IF($B18<$Z$18,$AA$14&"M / "&$Z$14&"H",MIN($AA$15,$AA$14+1+INT(($B18-$Z$18)/$Z$19))&"M / "&MIN($Z$15,$Z$14+1+INT(($B18-$Z$18)/$Z$19))&"H") -> 55M / 60H | S18: - | T18: 0 | U18: 0 | V18: 0 | W18: 0 | Y18: Início da vigência da nova regra (ano) | Z18: 2027
B19: 2024 | C19: 180610 | D19: 1041403 | E19: =C19/D19 -> 0.1734295 | F19: 211739 | G19: 1296107 | H19: =F19/G19 -> 0.16336537 | I19: 1412 | J19: 0.0477 | K19: - | L19: =IF($B19<$Z$18,$AA$14&"M / "&$Z$14&"H",$AA$15&"M / "&$Z$15&"H") -> 55M / 60H | M19: - | N19: 0 | O19: 0 | P19: 0 | Q19: 0 | R19: =IF($B19<$Z$18,$AA$14&"M / "&$Z$14&"H",MIN($AA$15,$AA$14+1+INT(($B19-$Z$18)/$Z$19))&"M / "&MIN($Z$15,$Z$14+1+INT(($B19-$Z$18)/$Z$19))&"H") -> 55M / 60H | S19: - | T19: 0 | U19: 0 | V19: 0 | W19: 0 | Y19: Intervalo entre acréscimos de 1 ano na transição (anos) | Z19: 2
B20: 2025 | C20: =D20*E20 -> 176201.89 | D20: 1061714 | E20: =AVERAGE($E$15:$E$19) -> 0.16595984 | F20: =G20*H20 -> 205285.49 | G20: 1308929 | H20: =AVERAGE($H$15:$H$19) -> 0.1568347 | I20: 1518 | J20: 0.039 | K20: - | L20: =IF($B20<$Z$18,$AA$14&"M / "&$Z$14&"H",$AA$15&"M / "&$Z$15&"H") -> 55M / 60H | M20: - | N20: 0 | O20: 0 | P20: 0 | Q20: 0 | R20: =IF($B20<$Z$18,$AA$14&"M / "&$Z$14&"H",MIN($AA$15,$AA$14+1+INT(($B20-$Z$18)/$Z$19))&"M / "&MIN($Z$15,$Z$14+1+INT(($B20-$Z$18)/$Z$19))&"H") -> 55M / 60H | S20: - | T20: 0 | U20: 0 | V20: 0 | W20: 0 | Y20: Pagamentos por ano (12 mensalidades + 13º) | Z20: 13
B21: 2026 | C21: =D21*E21 -> 178600.84 | D21: 1076169 | E21: =AVERAGE($E$15:$E$19) -> 0.16595984 | F21: =G21*H21 -> 207827.47 | G21: 1325137 | H21: =AVERAGE($H$15:$H$19) -> 0.1568347 | I21: 1621 | J21: 0.0376 | K21: 1 | L21: =IF($B21<$Z$18,$AA$14&"M / "&$Z$14&"H",$AA$15&"M / "&$Z$15&"H") -> 55M / 60H | M21: - | N21: 0 | O21: 0 | P21: 0 | Q21: 0 | R21: =IF($B21<$Z$18,$AA$14&"M / "&$Z$14&"H",MIN($AA$15,$AA$14+1+INT(($B21-$Z$18)/$Z$19))&"M / "&MIN($Z$15,$Z$14+1+INT(($B21-$Z$18)/$Z$19))&"H") -> 55M / 60H | S21: - | T21: 0 | U21: 0 | V21: 0 | W21: 0 | Y21: Observação: células em azul são entradas editáveis. Idade mínima vigente = A₀; Ī = idade média efetiva de concessão (média 2020–2025, tabela ao lado); a idade mínima proposta equipara a rural à urbana (65 anos, homens; 62, mulheres).
B22: 2027 | C22: =D22*E22 -> 180313.88 | D22: 1086491 | E22: =AVERAGE($E$15:$E$19) -> 0.16595984 | F22: =G22*H22 -> 210859.08 | G22: 1344467 | H22: =AVERAGE($H$15:$H$19) -> 0.1568347 | I22: 1716.9632 | J22: 0.0306 | K22: =K21*(1+J22) -> 1.0306 | L22: =IF($B22<$Z$18,$AA$14&"M / "&$Z$14&"H",$AA$15&"M / "&$Z$15&"H") -> 62M / 65H | M22: =SUMPRODUCT(($B$110:$B$245="Sem Transição")*$E$110:$E$245*$N$110:$U$245*(($D$110:$D$245+$N$109:$U$109)=$B22)) -> 97670.017 | N22: =M22*I22 -> 1.6769582e+08 | O22: =SUM(N$22:N22) -> 1.6769582e+08 | P22: =N22/$K22 -> 1.6271669e+08 | Q22: =SUM(P$22:P22) -> 1.6271669e+08 | R22: =IF($B22<$Z$18,$AA$14&"M / "&$Z$14&"H",MIN($AA$15,$AA$14+1+INT(($B22-$Z$18)/$Z$19))&"M / "&MIN($Z$15,$Z$14+1+INT(($B22-$Z$18)/$Z$19))&"H") -> 56M / 61H | S22: =SUMPRODUCT(($B$110:$B$245="Com Transição")*$E$110:$E$245*$N$110:$U$245*(($D$110:$D$245+$N$109:$U$109)=$B22)) -> 97670.017 | T22: =S22*I22 -> 1.6769582e+08 | U22: =SUM(T$22:T22) -> 1.6769582e+08 | V22: =T22/$K22 -> 1.6271669e+08 | W22: =SUM(V$22:V22) -> 1.6271669e+08 | Y22: Δ = atraso (meses) da concessão na regra vigente em relação à idade mínima vigente = 12 × (Ī − A₀), arredondado (0 se o seletor estiver em "Idade mínima vigente"). Início da vigência ≥ 2027; a transição soma 1 ano a cada [intervalo] anos até a idade proposta.
B23: 2028 | C23: =D23*E23 -> 181823.45 | D23: 1095587 | E23: =AVERAGE($E$15:$E$19) -> 0.16595984 | F23: =G23*H23 -> 213564.01 | G23: 1361714 | H23: =AVERAGE($H$15:$H$19) -> 0.1568347 | I23: 1811.9113 | J23: 0.03 | K23: =K22*(1+J23) -> 1.061518 | L23: =IF($B23<$Z$18,$AA$14&"M / "&$Z$14&"H",$AA$15&"M / "&$Z$15&"H") -> 62M / 65H | M23: =SUMPRODUCT(($B$110:$B$245="Sem Transição")*$E$110:$E$245*$N$110:$U$245*(($D$110:$D$245+$N$109:$U$109)=$B23)) -> 2541840 | N23: =M23*I23 -> 4.6055886e+09 | O23: =SUM(N$22:N23) -> 4.7732844e+09 | P23: =N23/$K23 -> 4.3386816e+09 | Q23: =SUM(P$22:P23) -> 4.5013982e+09 | R23: =IF($B23<$Z$18,$AA$14&"M / "&$Z$14&"H",MIN($AA$15,$AA$14+1+INT(($B23-$Z$18)/$Z$19))&"M / "&MIN($Z$15,$Z$14+1+INT(($B23-$Z$18)/$Z$19))&"H") -> 56M / 61H | S23: =SUMPRODUCT(($B$110:$B$245="Com Transição")*$E$110:$E$245*$N$110:$U$245*(($D$110:$D$245+$N$109:$U$109)=$B23)) -> 586837.78 | T23: =S23*I23 -> 1.063298e+09 | U23: =SUM(T$22:T23) -> 1.2309938e+09 | V23: =T23/$K23 -> 1.0016768e+09 | W23: =SUM(V$22:V23) -> 1.1643935e+09
B24: 2029 | C24: =D24*E24 -> 183806 | D24: 1107533 | E24: =AVERAGE($E$15:$E$19) -> 0.16595984 | F24: =G24*H24 -> 216512.66 | G24: 1380515 | H24: =AVERAGE($H$15:$H$19) -> 0.1568347 | I24: 1912.8347 | J24: 0.03 | K24: =K23*(1+J24) -> 1.0933635 | L24: =IF($B24<$Z$18,$AA$14&"M / "&$Z$14&"H",$AA$15&"M / "&$Z$15&"H") -> 62M / 65H | M24: =SUMPRODUCT(($B$110:$B$245="Sem Transição")*$E$110:$E$245*$N$110:$U$245*(($D$110:$D$245+$N$109:$U$109)=$B24)) -> 7537456.4 | N24: =M24*I24 -> 1.4417908e+10 | O24: =SUM(N$22:N24) -> 1.9191193e+10 | P24: =N24/$K24 -> 1.3186747e+10 | Q24: =SUM(P$22:P24) -> 1.7688145e+10 | R24: =IF($B24<$Z$18,$AA$14&"M / "&$Z$14&"H",MIN($AA$15,$AA$14+1+INT(($B24-$Z$18)/$Z$19))&"M / "&MIN($Z$15,$Z$14+1+INT(($B24-$Z$18)/$Z$19))&"H") -> 57M / 62H | S24: =SUMPRODUCT(($B$110:$B$245="Com Transição")*$E$110:$E$245*$N$110:$U$245*(($D$110:$D$245+$N$109:$U$109)=$B24)) -> 3175571.7 | T24: =S24*I24 -> 6.0743438e+09 | U24: =SUM(T$22:T24) -> 7.3053376e+09 | V24: =T24/$K24 -> 5.5556488e+09 | W24: =SUM(V$22:V24) -> 6.7200423e+09
B25: 2030 | C25: =D25*E25 -> 186296.9 | D25: 1122542 | E25: =AVERAGE($E$15:$E$19) -> 0.16595984 | F25: =G25*H25 -> 221038.75 | G25: 1409374 | H25: =AVERAGE($H$15:$H$19) -> 0.1568347 | I25: 2019.7622 | J25: 0.03 | K25: =K24*(1+J25) -> 1.1261644 | L25: =IF($B25<$Z$18,$AA$14&"M / "&$Z$14&"H",$AA$15&"M / "&$Z$15&"H") -> 62M / 65H | M25: =SUMPRODUCT(($B$110:$B$245="Sem Transição")*$E$110:$E$245*$N$110:$U$245*(($D$110:$D$245+$N$109:$U$109)=$B25)) -> 12706290 | N25: =M25*I25 -> 2.5663685e+10 | O25: =SUM(N$22:N25) -> 4.4854878e+10 | P25: =N25/$K25 -> 2.2788577e+10 | Q25: =SUM(P$22:P25) -> 4.0476722e+10 | R25: =IF($B25<$Z$18,$AA$14&"M / "&$Z$14&"H",MIN($AA$15,$AA$14+1+INT(($B25-$Z$18)/$Z$19))&"M / "&MIN($Z$15,$Z$14+1+INT(($B25-$Z$18)/$Z$19))&"H") -> 57M / 62H | S25: =SUMPRODUCT(($B$110:$B$245="Com Transição")*$E$110:$E$245*$N$110:$U$245*(($D$110:$D$245+$N$109:$U$109)=$B25)) -> 4836855.3 | T25: =S25*I25 -> 9.7692974e+09 | U25: =SUM(T$22:T25) -> 1.7074635e+10 | V25: =T25/$K25 -> 8.6748409e+09 | W25: =SUM(V$22:V25) -> 1.5394883e+10
B26: 2031 | C26: =D26*E26 -> 189167.34 | D26: 1139838 | E26: =AVERAGE($E$15:$E$19) -> 0.16595984 | F26: =G26*H26 -> 227466 | G26: 1450355 | H26: =AVERAGE($H$15:$H$19) -> 0.1568347 | I26: 2132.2629 | J26: 0.03 | K26: =K25*(1+J26) -> 1.1599494 | L26: =IF($B26<$Z$18,$AA$14&"M / "&$Z$14&"H",$AA$15&"M / "&$Z$15&"H") -> 62M / 65H | M26: =SUMPRODUCT(($B$110:$B$245="Sem Transição")*$E$110:$E$245*$N$110:$U$245*(($D$110:$D$245+$N$109:$U$109)=$B26)) -> 17949387 | N26: =M26*I26 -> 3.8272812e+10 | O26: =SUM(N$22:N26) -> 8.312769e+10 | P26: =N26/$K26 -> 3.2995243e+10 | Q26: =SUM(P$22:P26) -> 7.3471965e+10 | R26: =IF($B26<$Z$18,$AA$14&"M / "&$Z$14&"H",MIN($AA$15,$AA$14+1+INT(($B26-$Z$18)/$Z$19))&"M / "&MIN($Z$15,$Z$14+1+INT(($B26-$Z$18)/$Z$19))&"H") -> 58M / 63H | S26: =SUMPRODUCT(($B$110:$B$245="Com Transição")*$E$110:$E$245*$N$110:$U$245*(($D$110:$D$245+$N$109:$U$109)=$B26)) -> 7724101.3 | T26: =S26*I26 -> 1.6469815e+10 | U26: =SUM(T$22:T26) -> 3.354445e+10 | V26: =T26/$K26 -> 1.4198736e+10 | W26: =SUM(V$22:V26) -> 2.9593619e+10
B27: 2032 | C27: =D27*E27 -> 192404.22 | D27: 1159342 | E27: =AVERAGE($E$15:$E$19) -> 0.16595984 | F27: =G27*H27 -> 235068.87 | G27: 1498832 | H27: =AVERAGE($H$15:$H$19) -> 0.1568347 | I27: 2251.03 | J27: 0.03 | K27: =K26*(1+J27) -> 1.1947479 | L27: =IF($B27<$Z$18,$AA$14&"M / "&$Z$14&"H",$AA$15&"M / "&$Z$15&"H") -> 62M / 65H | M27: =SUMPRODUCT(($B$110:$B$245="Sem Transição")*$E$110:$E$245*$N$110:$U$245*(($D$110:$D$245+$N$109:$U$109)=$B27)) -> 22023217 | N27: =M27*I27 -> 4.9574922e+10 | O27: =SUM(N$22:N27) -> 1.3270261e+11 | P27: =N27/$K27 -> 4.1494045e+10 | Q27: =SUM(P$22:P27) -> 1.1496601e+11 | R27: =IF($B27<$Z$18,$AA$14&"M / "&$Z$14&"H",MIN($AA$15,$AA$14+1+INT(($B27-$Z$18)/$Z$19))&"M / "&MIN($Z$15,$Z$14+1+INT(($B27-$Z$18)/$Z$19))&"H") -> 58M / 63H | S27: =SUMPRODUCT(($B$110:$B$245="Com Transição")*$E$110:$E$245*$N$110:$U$245*(($D$110:$D$245+$N$109:$U$109)=$B27)) -> 10248731 | T27: =S27*I27 -> 2.3070201e+10 | U27: =SUM(T$22:T27) -> 5.6614651e+10 | V27: =T27/$K27 -> 1.9309682e+10 | W27: =SUM(V$22:V27) -> 4.8903301e+10
B28: 2033 | C28: =D28*E28 -> 195333.74 | D28: 1176994 | E28: =AVERAGE($E$15:$E$19) -> 0.16595984 | F28: =G28*H28 -> 243047.05 | G28: 1549702 | H28: =AVERAGE($H$15:$H$19) -> 0.1568347 | I28: 2361.7807 | J28: 0.03 | K28: =K27*(1+J28) -> 1.2305903 | L28: =IF($B28<$Z$18,$AA$14&"M / "&$Z$14&"H",$AA$15&"M / "&$Z$15&"H") -> 62M / 65H | M28: =SUMPRODUCT(($B$110:$B$245="Sem Transição")*$E$110:$E$245*$N$110:$U$245*(($D$110:$D$245+$N$109:$U$109)=$B28)) -> 25139114 | N28: =M28*I28 -> 5.9373074e+10 | O28: =SUM(N$22:N28) -> 1.9207569e+11 | P28: =N28/$K28 -> 4.8247637e+10 | Q28: =SUM(P$22:P28) -> 1.6321365e+11 | R28: =IF($B28<$Z$18,$AA$14&"M / "&$Z$14&"H",MIN($AA$15,$AA$14+1+INT(($B28-$Z$18)/$Z$19))&"M / "&MIN($Z$15,$Z$14+1+INT(($B28-$Z$18)/$Z$19))&"H") -> 59M / 64H | S28: =SUMPRODUCT(($B$110:$B$245="Com Transição")*$E$110:$E$245*$N$110:$U$245*(($D$110:$D$245+$N$109:$U$109)=$B28)) -> 13334107 | T28: =S28*I28 -> 3.1492235e+10 | U28: =SUM(T$22:T28) -> 8.8106886e+10 | V28: =T28/$K28 -> 2.5591162e+10 | W28: =SUM(V$22:V28) -> 7.4494463e+10
B29: 2034 | C29: =D29*E29 -> 198579.92 | D29: 1196554 | E29: =AVERAGE($E$15:$E$19) -> 0.16595984 | F29: =G29*H29 -> 250194.8 | G29: 1595277 | H29: =AVERAGE($H$15:$H$19) -> 0.1568347 | I29: 2476.7994 | J29: 0.03 | K29: =K28*(1+J29) -> 1.267508 | L29: =IF($B29<$Z$18,$AA$14&"M / "&$Z$14&"H",$AA$15&"M / "&$Z$15&"H") -> 62M / 65H | M29: =SUMPRODUCT(($B$110:$B$245="Sem Transição")*$E$110:$E$245*$N$110:$U$245*(($D$110:$D$245+$N$109:$U$109)=$B29)) -> 26885932 | N29: =M29*I29 -> 6.6591059e+10 | O29: =SUM(N$22:N29) -> 2.5866674e+11 | P29: =N29/$K29 -> 5.2536993e+10 | Q29: =SUM(P$22:P29) -> 2.1575064e+11 | R29: =IF($B29<$Z$18,$AA$14&"M / "&$Z$14&"H",MIN($AA$15,$AA$14+1+INT(($B29-$Z$18)/$Z$19))&"M / "&MIN($Z$15,$Z$14+1+INT(($B29-$Z$18)/$Z$19))&"H") -> 59M / 64H | S29: =SUMPRODUCT(($B$110:$B$245="Com Transição")*$E$110:$E$245*$N$110:$U$245*(($D$110:$D$245+$N$109:$U$109)=$B29)) -> 16075067 | T29: =S29*I29 -> 3.9814716e+10 | U29: =SUM(T$22:T29) -> 1.279216e+11 | V29: =T29/$K29 -> 3.1411806e+10 | W29: =SUM(V$22:V29) -> 1.0590627e+11
B30: 2035 | C30: =D30*E30 -> 203288.86 | D30: 1224928 | E30: =AVERAGE($E$15:$E$19) -> 0.16595984 | F30: =G30*H30 -> 255651.39 | G30: 1630069 | H30: =AVERAGE($H$15:$H$19) -> 0.1568347 | I30: 2596.4288 | J30: 0.03 | K30: =K29*(1+J30) -> 1.3055332 | L30: =IF($B30<$Z$18,$AA$14&"M / "&$Z$14&"H",$AA$15&"M / "&$Z$15&"H") -> 62M / 65H | M30: =SUMPRODUCT(($B$110:$B$245="Sem Transição")*$E$110:$E$245*$N$110:$U$245*(($D$110:$D$245+$N$109:$U$109)=$B30)) -> 27470758 | N30: =M30*I30 -> 7.1325868e+10 | O30: =SUM(N$22:N30) -> 3.2999261e+11 | P30: =N30/$K30 -> 5.4633513e+10 | Q30: =SUM(P$22:P30) -> 2.7038415e+11 | R30: =IF($B30<$Z$18,$AA$14&"M / "&$Z$14&"H",MIN($AA$15,$AA$14+1+INT(($B30-$Z$18)/$Z$19))&"M / "&MIN($Z$15,$Z$14+1+INT(($B30-$Z$18)/$Z$19))&"H") -> 60M / 65H | S30: =SUMPRODUCT(($B$110:$B$245="Com Transição")*$E$110:$E$245*$N$110:$U$245*(($D$110:$D$245+$N$109:$U$109)=$B30)) -> 19400085 | T30: =S30*I30 -> 5.037094e+10 | U30: =SUM(T$22:T30) -> 1.7829254e+11 | V30: =T30/$K30 -> 3.8582656e+10 | W30: =SUM(V$22:V30) -> 1.4448893e+11
B31: 2036 | C31: =D31*E31 -> 209615.41 | D31: 1263049 | E31: =AVERAGE($E$15:$E$19) -> 0.16595984 | F31: =G31*H31 -> 258603.02 | G31: 1648889 | H31: =AVERAGE($H$15:$H$19) -> 0.1568347 | I31: 2720.2784 | J31: 0.03 | K31: =K30*(1+J31) -> 1.3446992 | L31: =IF($B31<$Z$18,$AA$14&"M / "&$Z$14&"H",$AA$15&"M / "&$Z$15&"H") -> 62M / 65H | M31: =SUMPRODUCT(($B$110:$B$245="Sem Transição")*$E$110:$E$245*$N$110:$U$245*(($D$110:$D$245+$N$109:$U$109)=$B31)) -> 28128863 | N31: =M31*I31 -> 7.651834e+10 | O31: =SUM(N$22:N31) -> 4.0651095e+11 | P31: =N31/$K31 -> 5.6903683e+10 | Q31: =SUM(P$22:P31) -> 3.2728784e+11 | R31: =IF($B31<$Z$18,$AA$14&"M / "&$Z$14&"H",MIN($AA$15,$AA$14+1+INT(($B31-$Z$18)/$Z$19))&"M / "&MIN($Z$15,$Z$14+1+INT(($B31-$Z$18)/$Z$19))&"H") -> 60M / 65H | S31: =SUMPRODUCT(($B$110:$B$245="Com Transição")*$E$110:$E$245*$N$110:$U$245*(($D$110:$D$245+$N$109:$U$109)=$B31)) -> 22363565 | T31: =S31*I31 -> 6.0835123e+10 | U31: =SUM(T$22:T31) -> 2.3912767e+11 | V31: =T31/$K31 -> 4.5240691e+10 | W31: =SUM(V$22:V31) -> 1.8972962e+11
B32: 2037 | C32: =D32*E32 -> 216931.75 | D32: 1307134 | E32: =AVERAGE($E$15:$E$19) -> 0.16595984 | F32: =G32*H32 -> 259555.47 | G32: 1654962 | H32: =AVERAGE($H$15:$H$19) -> 0.1568347 | I32: 2848.6756 | J32: 0.03 | K32: =K31*(1+J32) -> 1.3850402 | L32: =IF($B32<$Z$18,$AA$14&"M / "&$Z$14&"H",$AA$15&"M / "&$Z$15&"H") -> 62M / 65H | M32: =SUMPRODUCT(($B$110:$B$245="Sem Transição")*$E$110:$E$245*$N$110:$U$245*(($D$110:$D$245+$N$109:$U$109)=$B32)) -> 28838866 | N32: =M32*I32 -> 8.2152574e+10 | O32: =SUM(N$22:N32) -> 4.8866353e+11 | P32: =N32/$K32 -> 5.9314215e+10 | Q32: =SUM(P$22:P32) -> 3.8660205e+11 | R32: =IF($B32<$Z$18,$AA$14&"M / "&$Z$14&"H",MIN($AA$15,$AA$14+1+INT(($B32-$Z$18)/$Z$19))&"M / "&MIN($Z$15,$Z$14+1+INT(($B32-$Z$18)/$Z$19))&"H") -> 61M / 65H | S32: =SUMPRODUCT(($B$110:$B$245="Com Transição")*$E$110:$E$245*$N$110:$U$245*(($D$110:$D$245+$N$109:$U$109)=$B32)) -> 24564786 | T32: =S32*I32 -> 6.9977105e+10 | U32: =SUM(T$22:T32) -> 3.0910477e+11 | V32: =T32/$K32 -> 5.0523518e+10 | W32: =SUM(V$22:V32) -> 2.4025313e+11
B33: 2038 | C33: =D33*E33 -> 224518.11 | D33: 1352846 | E33: =AVERAGE($E$15:$E$19) -> 0.16595984 | F33: =G33*H33 -> 260004.02 | G33: 1657822 | H33: =AVERAGE($H$15:$H$19) -> 0.1568347 | I33: 2980.8541 | J33: 0.03 | K33: =K32*(1+J33) -> 1.4265914 | L33: =IF($B33<$Z$18,$AA$14&"M / "&$Z$14&"H",$AA$15&"M / "&$Z$15&"H") -> 62M / 65H | M33: =SUMPRODUCT(($B$110:$B$245="Sem Transição")*$E$110:$E$245*$N$110:$U$245*(($D$110:$D$245+$N$109:$U$109)=$B33)) -> 29562000 | N33: =M33*I33 -> 8.812001e+10 | O33: =SUM(N$22:N33) -> 5.7678354e+11 | P33: =N33/$K33 -> 6.176962e+10 | Q33: =SUM(P$22:P33) -> 4.4837167e+11 | R33: =IF($B33<$Z$18,$AA$14&"M / "&$Z$14&"H",MIN($AA$15,$AA$14+1+INT(($B33-$Z$18)/$Z$19))&"M / "&MIN($Z$15,$Z$14+1+INT(($B33-$Z$18)/$Z$19))&"H") -> 61M / 65H | S33: =SUMPRODUCT(($B$110:$B$245="Com Transição")*$E$110:$E$245*$N$110:$U$245*(($D$110:$D$245+$N$109:$U$109)=$B33)) -> 26551405 | T33: =S33*I33 -> 7.9145866e+10 | U33: =SUM(T$22:T33) -> 3.8825064e+11 | V33: =T33/$K33 -> 5.5479e+10 | W33: =SUM(V$22:V33) -> 2.9573213e+11
B34: 2039 | C34: =D34*E34 -> 231423.2 | D34: 1394453 | E34: =AVERAGE($E$15:$E$19) -> 0.16595984 | F34: =G34*H34 -> 260414.3 | G34: 1660438 | H34: =AVERAGE($H$15:$H$19) -> 0.1568347 | I34: 3117.9734 | J34: 0.03 | K34: =K33*(1+J34) -> 1.4693892 | L34: =IF($B34<$Z$18,$AA$14&"M / "&$Z$14&"H",$AA$15&"M / "&$Z$15&"H") -> 62M / 65H | M34: =SUMPRODUCT(($B$110:$B$245="Sem Transição")*$E$110:$E$245*$N$110:$U$245*(($D$110:$D$245+$N$109:$U$109)=$B34)) -> 30262191 | N34: =M34*I34 -> 9.4356708e+10 | O34: =SUM(N$22:N34) -> 6.7114024e+11 | P34: =N34/$K34 -> 6.421492e+10 | Q34: =SUM(P$22:P34) -> 5.1258659e+11 | R34: =IF($B34<$Z$18,$AA$14&"M / "&$Z$14&"H",MIN($AA$15,$AA$14+1+INT(($B34-$Z$18)/$Z$19))&"M / "&MIN($Z$15,$Z$14+1+INT(($B34-$Z$18)/$Z$19))&"H") -> 62M / 65H | S34: =SUMPRODUCT(($B$110:$B$245="Com Transição")*$E$110:$E$245*$N$110:$U$245*(($D$110:$D$245+$N$109:$U$109)=$B34)) -> 28861573 | T34: =S34*I34 -> 8.9989616e+10 | U34: =SUM(T$22:T34) -> 4.7824025e+11 | V34: =T34/$K34 -> 6.1242874e+10 | W34: =SUM(V$22:V34) -> 3.5697501e+11
... B55: 2060 | C55: =D55*E55 -> 243093.33 | D55: 1464772 | E55: =AVERAGE($E$15:$E$19) -> 0.16595984 | F55: =G55*H55 -> 225132.61 | G55: 1435477 | H55: =AVERAGE($H$15:$H$19) -> 0.1568347 | I55: 7299.2611 | J55: 0.03 | K55: =K54*(1+J55) -> 2.7334967 | L55: =IF($B55<$Z$18,$AA$14&"M / "&$Z$14&"H",$AA$15&"M / "&$Z$15&"H") -> 62M / 65H | M55: =SUMPRODUCT(($B$110:$B$245="Sem Transição")*$E$110:$E$245*$N$110:$U$245*(($D$110:$D$245+$N$109:$U$109)=$B55)) -> 30995845 | N55: =M55*I55 -> 2.2624676e+11 | O55: =SUM(N$22:N55) -> 4.0326361e+12 | P55: =N55/$K55 -> 8.276826e+10 | Q55: =SUM(P$22:P55) -> 2.1230628e+12 | R55: =IF($B55<$Z$18,$AA$14&"M / "&$Z$14&"H",MIN($AA$15,$AA$14+1+INT(($B55-$Z$18)/$Z$19))&"M / "&MIN($Z$15,$Z$14+1+INT(($B55-$Z$18)/$Z$19))&"H") -> 62M / 65H | S55: =SUMPRODUCT(($B$110:$B$245="Com Transição")*$E$110:$E$245*$N$110:$U$245*(($D$110:$D$245+$N$109:$U$109)=$B55)) -> 30995845 | T55: =S55*I55 -> 2.2624676e+11 | U55: =SUM(T$22:T55) -> 3.8397361e+12 | V55: =T55/$K55 -> 8.276826e+10 | W55: =SUM(V$22:V55) -> 1.9674513e+12
B56: Fonte: AEPS (Publicações de 2012, 2015, 2018, 2021 e 2024), PLDO 2027 - Anexo IV.10 - Projeções Atuariais RGPS, Projeções da População (Revisão 2024) do IBGE e base Concedidos (SUIBE/INSS) para a idade média efetiva. Valores em R$ nominais e em R$ de 2026 (reais).
B59: Memória de Cálculo das Colunas M e S — Tabelas Auxiliares (agrupadas: use o [+] à esquerda da linha para expandir)
B60: Esta seção calcula, por coorte, quantos pagamentos cada segurado deixa de receber com a regra proposta. As tabelas auxiliares H(X; n) e C(z) alimentam a tabela por coorte, sexo e cenário, que alimenta as colunas M e S da tabela principal.
B63: Tabela Auxiliar — Meses Recebidos no Ano por Grupo de Meses de Entrada, H(X; n) | Q63: Soma Acumulada, C(z)
B64: X \ n | C64: 0 | D64: 1 | E64: 2 | F64: 3 | G64: 4 | H64: 5 | I64: 6 | J64: 7 | K64: 8 | L64: 9 | M64: 10 | N64: 11 | O64: 12 | Q64: z | R64: C(z)
B65: 0 | C65: =INDEX($R$65:$R$101,$B65+13)-INDEX($R$65:$R$101,$B65-C$64+13) -> 0 | D65: =INDEX($R$65:$R$101,$B65+13)-INDEX($R$65:$R$101,$B65-D$64+13) -> 0 | E65: =INDEX($R$65:$R$101,$B65+13)-INDEX($R$65:$R$101,$B65-E$64+13) -> 0 | F65: =INDEX($R$65:$R$101,$B65+13)-INDEX($R$65:$R$101,$B65-F$64+13) -> 0 | G65: =INDEX($R$65:$R$101,$B65+13)-INDEX($R$65:$R$101,$B65-G$64+13) -> 0 | H65: =INDEX($R$65:$R$101,$B65+13)-INDEX($R$65:$R$101,$B65-H$64+13) -> 0 | I65: =INDEX($R$65:$R$101,$B65+13)-INDEX($R$65:$R$101,$B65-I$64+13) -> 0 | J65: =INDEX($R$65:$R$101,$B65+13)-INDEX($R$65:$R$101,$B65-J$64+13) -> 0 | ... O65: =INDEX($R$65:$R$101,$B65+13)-INDEX($R$65:$R$101,$B65-O$64+13) -> 0 | Q65: -12 | R65: =IF(Q65<=0,0,IF(Q65<=12,Q65*(Q65+1)/2,78+12*(Q65-12))) -> 0
...

Sheet Transição Uniforme 10 Anos
B2: ="Análise da Economia Estimada com a Proposta de Aumento da Idade Mínima para Aposentadoria Rural — Transição Gradual de "&$Z$19&" Anos" -> Análise da Economia Estimada com a Proposta de Aumento da Idade Mínima para Aposentadoria Rural — Transição Gradual de 10 Anos
B3: Fluxo de Concessões e Parâmetros Econômicos | L3: Sem Transição | R3: ="Transição Uniforme de "&$Z$19&" anos (H e M)" -> Transição Uniforme de 10 anos (H e M)
B4: Ano | C4: Aposentadorias Rurais por Idade Concedidas para o Sexo Masculino | D4: População de Homens com 60 anos | E4: Constância de Incidência (Homens) | F4: Aposentadorias Rurais por Idade Concedidas para o Sexo Feminino | G4: População de Mulheres com 55 anos | H4: Constância de Incidência (Mulheres) | I4: Salário Mínimo | J4: Inflação (INPC) | K4: Inflação Acumulada | L4: Idade Mínima | M4: Emissões Adiadas | N4: Economia Nominal Projetada | O4: Economia Nominal Projetada Acumulada | P4: Economia Real Projetada | Q4: Economia Real Projetada Acumulada | R4: Idade Mínima | S4: Emissões Adiadas | T4: Economia Nominal Projetada | U4: Economia Nominal Projetada Acumulada | V4: Economia Real Projetada | W4: Economia Real Projetada Acumulada
B5: 2010 | C5: ='Transição 9 H e 13 M Anos'!C5 -> 147356 | D5: ='Transição 9 H e 13 M Anos'!D5 -> 684213 | E5: =C5/D5 -> 0.21536568 | F5: ='Transição 9 H e 13 M Anos'!F5 -> 199978 | G5: ='Transição 9 H e 13 M Anos'!G5 -> 958517 | H5: =F5/G5 -> 0.20863271 | I5: ='Transição 9 H e 13 M Anos'!I5 -> 510 | J5: ='Transição 9 H e 13 M Anos'!J5 -> 0.064652 | K5: - | L5: =IF($B5<$Z$18,$AA$14&"M / "&$Z$14&"H",$AA$15&"M / "&$Z$15&"H") -> 55M / 60H | M5: - | N5: 0 | O5: 0 | P5: 0 | Q5: 0 | R5: =IF($B5<$Z$18,$AA$14&"M / "&$Z$14&"H",ROUND($AA$14+INDEX($F$65:$F$108,$B5-2026)/12,1)&"M / "&ROUND($Z$14+INDEX($E$65:$E$108,$B5-2026)/12,1)&"H") -> 55M / 60H | S5: - | T5: 0 | U5: 0 | V5: 0 | W5: 0 | Y5: Cenário de Referência — Idade de Concessão na Regra Vigente | AC5: Resultado do Cenário Selecionado | AG5: Idade Média Efetiva na DIB (Rural)
B6: 2011 | C6: ='Transição 9 H e 13 M Anos'!C6 -> 141310 | D6: ='Transição 9 H e 13 M Anos'!D6 -> 709218 | E6: =C6/D6 -> 0.19924762 | F6: ='Transição 9 H e 13 M Anos'!F6 -> 201742 | G6: ='Transição 9 H e 13 M Anos'!G6 -> 991806 | H6: =F6/G6 -> 0.20340873 | I6: ='Transição 9 H e 13 M Anos'!I6 -> 540 | J6: ='Transição 9 H e 13 M Anos'!J6 -> 0.060799 | K6: - | L6: =IF($B6<$Z$18,$AA$14&"M / "&$Z$14&"H",$AA$15&"M / "&$Z$15&"H") -> 55M / 60H | M6: - | N6: 0 | O6: 0 | P6: 0 | Q6: 0 | R6: =IF($B6<$Z$18,$AA$14&"M / "&$Z$14&"H",ROUND($AA$14+INDEX($F$65:$F$108,$B6-2026)/12,1)&"M / "&ROUND($Z$14+INDEX($E$65:$E$108,$B6-2026)/12,1)&"H") -> 55M / 60H | S6: - | T6: 0 | U6: 0 | V6: 0 | W6: 0 | Y6: Idade de concessão adotada (selecionar na lista): | Z6: Idade média efetiva | AC6: Economia Real Acumulada | AD6: Até 2030 | AE6: Até 2060 | AG6: Ano | AH6: Homens | AI6: Mulheres
B7: 2012 | C7: ='Transição 9 H e 13 M Anos'!C7 -> 148810 | D7: ='Transição 9 H e 13 M Anos'!D7 -> 734954 | E7: =C7/D7 -> 0.20247526 | F7: ='Transição 9 H e 13 M Anos'!F7 -> 203190 | G7: ='Transição 9 H e 13 M Anos'!G7 -> 1024678 | H7: =F7/G7 -> 0.19829644 | I7: ='Transição 9 H e 13 M Anos'!I7 -> 622 | J7: ='Transição 9 H e 13 M Anos'!J7 -> 0.061978 | K7: - | L7: =IF($B7<$Z$18,$AA$14&"M / "&$Z$14&"H",$AA$15&"M / "&$Z$15&"H") -> 55M / 60H | M7: - | N7: 0 | O7: 0 | P7: 0 | Q7: 0 | R7: =IF($B7<$Z$18,$AA$14&"M / "&$Z$14&"H",ROUND($AA$14+INDEX($F$65:$F$108,$B7-2026)/12,1)&"M / "&ROUND($Z$14+INDEX($E$65:$E$108,$B7-2026)/12,1)&"H") -> 55M / 60H | S7: - | T7: 0 | U7: 0 | V7: 0 | W7: 0 | Y7: Idade média efetiva: concessão aos Ī anos, em média (Δ meses após a idade mínima vigente). | AC7: Sem Transição | AD7: =Q25 -> 4.0476722e+10 | AE7: =Q55 -> 2.1230628e+12 | AG7: 2020 | AH7: ='Transição 9 H e 13 M Anos'!AH7 -> 60.56 | AI7: ='Transição 9 H e 13 M Anos'!AI7 -> 56.08
B8: 2013 | C8: ='Transição 9 H e 13 M Anos'!C8 -> 148885 | D8: ='Transição 9 H e 13 M Anos'!D8 -> 761573 | E8: =C8/D8 -> 0.19549669 | F8: ='Transição 9 H e 13 M Anos'!F8 -> 209735 | G8: ='Transição 9 H e 13 M Anos'!G8 -> 1057683 | H8: =F8/G8 -> 0.19829665 | I8: ='Transição 9 H e 13 M Anos'!I8 -> 678 | J8: ='Transição 9 H e 13 M Anos'!J8 -> 0.055627 | K8: - | L8: =IF($B8<$Z$18,$AA$14&"M / "&$Z$14&"H",$AA$15&"M / "&$Z$15&"H") -> 55M / 60H | M8: - | N8: 0 | O8: 0 | P8: 0 | Q8: 0 | R8: =IF($B8<$Z$18,$AA$14&"M / "&$Z$14&"H",ROUND($AA$14+INDEX($F$65:$F$108,$B8-2026)/12,1)&"M / "&ROUND($Z$14+INDEX($E$65:$E$108,$B8-2026)/12,1)&"H") -> 55M / 60H | S8: - | T8: 0 | U8: 0 | V8: 0 | W8: 0 | Y8: Idade mínima vigente: concessão exatamente aos 60 (H) e 55 (M) anos (premissa original). | AC8: ="Transição Uniforme de "&$Z$19&" anos (H e M)" -> Transição Uniforme de 10 anos (H e M) | AD8: =W25 -> 1.7664394e+10 | AE8: =W55 -> 2.0263571e+12 | AG8: 2021 | AH8: ='Transição 9 H e 13 M Anos'!AH8 -> 60.74 | AI8: ='Transição 9 H e 13 M Anos'!AI8 -> 56.24
B9: 2014 | C9: ='Transição 9 H e 13 M Anos'!C9 -> 148068 | D9: ='Transição 9 H e 13 M Anos'!D9 -> 789185 | E9: =C9/D9 -> 0.18762141 | F9: ='Transição 9 H e 13 M Anos'!F9 -> 189793 | G9: ='Transição 9 H e 13 M Anos'!G9 -> 1090856 | H9: =F9/G9 -> 0.17398538 | I9: ='Transição 9 H e 13 M Anos'!I9 -> 724 | J9: ='Transição 9 H e 13 M Anos'!J9 -> 0.062283 | K9: - | L9: =IF($B9<$Z$18,$AA$14&"M / "&$Z$14&"H",$AA$15&"M / "&$Z$15&"H") -> 55M / 60H | M9: - | N9: 0 | O9: 0 | P9: 0 | Q9: 0 | R9: =IF($B9<$Z$18,$AA$14&"M / "&$Z$14&"H",ROUND($AA$14+INDEX($F$65:$F$108,$B9-2026)/12,1)&"M / "&ROUND($Z$14+INDEX($E$65:$E$108,$B9-2026)/12,1)&"H") -> 55M / 60H | S9: - | T9: 0 | U9: 0 | V9: 0 | W9: 0 | Y9: Observação: define o ponto de partida (Δ) nos cenários sem e com transição. | AC9: =IF($C$118="OK","R$ bi deflacionados; atualizam com o seletor ao lado.","ATENÇÃO: ampliar as colunas j da memória de cálculo.") -> R$ bi deflacionados; atualizam com o seletor ao lado. | AG9: 2022 | AH9: ='Transição 9 H e 13 M Anos'!AH9 -> 60.78 | AI9: ='Transição 9 H e 13 M Anos'!AI9 -> 56.31
B10: 2015 | C10: ='Transição 9 H e 13 M Anos'!C10 -> 123166 | D10: ='Transição 9 H e 13 M Anos'!D10 -> 817332 | E10: =C10/D10 -> 0.15069274 | F10: ='Transição 9 H e 13 M Anos'!F10 -> 163510 | G10: ='Transição 9 H e 13 M Anos'!G10 -> 1123521 | H10: =F10/G10 -> 0.14553355 | I10: ='Transição 9 H e 13 M Anos'!I10 -> 788 | J10: ='Transição 9 H e 13 M Anos'!J10 -> 0.112762 | K10: - | L10: =IF($B10<$Z$18,$AA$14&"M / "&$Z$14&"H",$AA$15&"M / "&$Z$15&"H") -> 55M / 60H | M10: - | N10: 0 | O10: 0 | P10: 0 | Q10: 0 | R10: =IF($B10<$Z$18,$AA$14&"M / "&$Z$14&"H",ROUND($AA$14+INDEX($F$65:$F$108,$B10-2026)/12,1)&"M / "&ROUND($Z$14+INDEX($E$65:$E$108,$B10-2026)/12,1)&"H") -> 55M / 60H | S10: - | T10: 0 | U10: 0 | V10: 0 | W10: 0 | AG10: 2023 | AH10: ='Transição 9 H e 13 M Anos'!AH10 -> 60.82 | AI10: ='Transição 9 H e 13 M Anos'!AI10 -> 56.48
B11: 2016 | C11: ='Transição 9 H e 13 M Anos'!C11 -> 137321 | D11: ='Transição 9 H e 13 M Anos'!D11 -> 845348 | E11: =C11/D11 -> 0.16244316 | F11: ='Transição 9 H e 13 M Anos'!F11 -> 168089 | G11: ='Transição 9 H e 13 M Anos'!G11 -> 1155913 | H11: =F11/G11 -> 0.14541665 | I11: ='Transição 9 H e 13 M Anos'!I11 -> 880 | J11: ='Transição 9 H e 13 M Anos'!J11 -> 0.0658 | K11: - | L11: =IF($B11<$Z$18,$AA$14&"M / "&$Z$14&"H",$AA$15&"M / "&$Z$15&"H") -> 55M / 60H | M11: - | N11: 0 | O11: 0 | P11: 0 | Q11: 0 | R11: =IF($B11<$Z$18,$AA$14&"M / "&$Z$14&"H",ROUND($AA$14+INDEX($F$65:$F$108,$B11-2026)/12,1)&"M / "&ROUND($Z$14+INDEX($E$65:$E$108,$B11-2026)/12,1)&"H") -> 55M / 60H | S11: - | T11: 0 | U11: 0 | V11: 0 | W11: 0 | AC11: Comparativo — Cenário Com Transição | AG11: 2024 | AH11: ='Transição 9 H e 13 M Anos'!AH11 -> 60.79 | AI11: ='Transição 9 H e 13 M Anos'!AI11 -> 56.58
B12: 2017 | C12: ='Transição 9 H e 13 M Anos'!C12 -> 143953 | D12: ='Transição 9 H e 13 M Anos'!D12 -> 872932 | E12: =C12/D12 -> 0.16490746 | F12: ='Transição 9 H e 13 M Anos'!F12 -> 180043 | G12: ='Transição 9 H e 13 M Anos'!G12 -> 1186329 | H12: =F12/G12 -> 0.15176481 | I12: ='Transição 9 H e 13 M Anos'!I12 -> 937 | J12: ='Transição 9 H e 13 M Anos'!J12 -> 0.020669 | K12: - | L12: =IF($B12<$Z$18,$AA$14&"M / "&$Z$14&"H",$AA$15&"M / "&$Z$15&"H") -> 55M / 60H | M12: - | N12: 0 | O12: 0 | P12: 0 | Q12: 0 | R12: =IF($B12<$Z$18,$AA$14&"M / "&$Z$14&"H",ROUND($AA$14+INDEX($F$65:$F$108,$B12-2026)/12,1)&"M / "&ROUND($Z$14+INDEX($E$65:$E$108,$B12-2026)/12,1)&"H") -> 55M / 60H | S12: - | T12: 0 | U12: 0 | V12: 0 | W12: 0 | Y12: Parâmetros de Regra e de Cálculo | AC12: Economia Real Acumulada | AD12: Até 2030 | AE12: Até 2060 | AG12: 2025 | AH12: ='Transição 9 H e 13 M Anos'!AH12 -> 60.72 | AI12: ='Transição 9 H e 13 M Anos'!AI12 -> 56.29
B13: 2018 | C13: ='Transição 9 H e 13 M Anos'!C13 -> 128360 | D13: ='Transição 9 H e 13 M Anos'!D13 -> 900259 | E13: =C13/D13 -> 0.14258119 | F13: ='Transição 9 H e 13 M Anos'!F13 -> 166897 | G13: ='Transição 9 H e 13 M Anos'!G13 -> 1211645 | H13: =F13/G13 -> 0.13774414 | I13: ='Transição 9 H e 13 M Anos'!I13 -> 954 | J13: ='Transição 9 H e 13 M Anos'!J13 -> 0.03434 | K13: - | L13: =IF($B13<$Z$18,$AA$14&"M / "&$Z$14&"H",$AA$15&"M / "&$Z$15&"H") -> 55M / 60H | M13: - | N13: 0 | O13: 0 | P13: 0 | Q13: 0 | R13: =IF($B13<$Z$18,$AA$14&"M / "&$Z$14&"H",ROUND($AA$14+INDEX($F$65:$F$108,$B13-2026)/12,1)&"M / "&ROUND($Z$14+INDEX($E$65:$E$108,$B13-2026)/12,1)&"H") -> 55M / 60H | S13: - | T13: 0 | U13: 0 | V13: 0 | W13: 0 | Y13: Parâmetro | Z13: Homens | AA13: Mulheres | AC13: ='Transição 9 H e 13 M Anos'!AC8 -> Transição de 9 anos (H) e 13 anos (M) | AD13: ='Transição 9 H e 13 M Anos'!AD8 -> 1.5394883e+10 | AE13: ='Transição 9 H e 13 M Anos'!AE8 -> 1.9674513e+12 | AG13: Média 2020–2025 | AH13: =AVERAGE(AH7:AH12) -> 60.735 | AI13: =AVERAGE(AI7:AI12) -> 56.33
B14: 2019 | C14: ='Transição 9 H e 13 M Anos'!C14 -> 112392 | D14: ='Transição 9 H e 13 M Anos'!D14 -> 927304 | E14: =C14/D14 -> 0.12120297 | F14: ='Transição 9 H e 13 M Anos'!F14 -> 146999 | G14: ='Transição 9 H e 13 M Anos'!G14 -> 1238650 | H14: =F14/G14 -> 0.11867679 | I14: ='Transição 9 H e 13 M Anos'!I14 -> 998 | J14: ='Transição 9 H e 13 M Anos'!J14 -> 0.044816 | K14: - | L14: =IF($B14<$Z$18,$AA$14&"M / "&$Z$14&"H",$AA$15&"M / "&$Z$15&"H") -> 55M / 60H | M14: - | N14: 0 | O14: 0 | P14: 0 | Q14: 0 | R14: =IF($B14<$Z$18,$AA$14&"M / "&$Z$14&"H",ROUND($AA$14+INDEX($F$65:$F$108,$B14-2026)/12,1)&"M / "&ROUND($Z$14+INDEX($E$65:$E$108,$B14-2026)/12,1)&"H") -> 55M / 60H | S14: - | T14: 0 | U14: 0 | V14: 0 | W14: 0 | Y14: Idade mínima vigente (anos) | Z14: ='Transição 9 H e 13 M Anos'!Z14 -> 60 | AA14: ='Transição 9 H e 13 M Anos'!AA14 -> 55 | AC14: =AC8 -> Transição Uniforme de 10 anos (H e M) | AD14: =AD8 -> 1.7664394e+10 | AE14: =AE8 -> 2.0263571e+12 | AG14: Projeção 2026–2060 | AH14: =AH13 -> 60.735 | AI14: =AI13 -> 56.33
B15: 2020 | C15: ='Transição 9 H e 13 M Anos'!C15 -> 125151 | D15: ='Transição 9 H e 13 M Anos'!D15 -> 952510 | E15: =C15/D15 -> 0.13139075 | F15: ='Transição 9 H e 13 M Anos'!F15 -> 154416 | G15: ='Transição 9 H e 13 M Anos'!G15 -> 1259472 | H15: =F15/G15 -> 0.12260376 | I15: ='Transição 9 H e 13 M Anos'!I15 -> 1045 | J15: ='Transição 9 H e 13 M Anos'!J15 -> 0.054473 | K15: - | L15: =IF($B15<$Z$18,$AA$14&"M / "&$Z$14&"H",$AA$15&"M / "&$Z$15&"H") -> 55M / 60H | M15: - | N15: 0 | O15: 0 | P15: 0 | Q15: 0 | R15: =IF($B15<$Z$18,$AA$14&"M / "&$Z$14&"H",ROUND($AA$14+INDEX($F$65:$F$108,$B15-2026)/12,1)&"M / "&ROUND($Z$14+INDEX($E$65:$E$108,$B15-2026)/12,1)&"H") -> 55M / 60H | S15: - | T15: 0 | U15: 0 | V15: 0 | W15: 0 | Y15: Idade mínima proposta — equiparada à urbana (anos) | Z15: ='Transição 9 H e 13 M Anos'!Z15 -> 65 | AA15: ='Transição 9 H e 13 M Anos'!AA15 -> 62 | AC15: Diferença | AD15: =AD14-AD13 -> 2.2695107e+09 | AE15: =AE14-AE13 -> 5.8905859e+10 | AG15: Observação: idade média na data de início do benefício (DIB) das aposentadorias por idade rurais concedidas em cada ano. A média simples 2020–2025 é mantida constante até 2060 e alimenta Ī (Z16:AA16).
B16: 2021 | C16: ='Transição 9 H e 13 M Anos'!C16 -> 144418 | D16: ='Transição 9 H e 13 M Anos'!D16 -> 974702 | E16: =C16/D16 -> 0.14816631 | F16: ='Transição 9 H e 13 M Anos'!F16 -> 177797 | G16: ='Transição 9 H e 13 M Anos'!G16 -> 1271298 | H16: =F16/G16 -> 0.1398547 | I16: ='Transição 9 H e 13 M Anos'!I16 -> 1100 | J16: ='Transição 9 H e 13 M Anos'!J16 -> 0.101602 | K16: - | L16: =IF($B16<$Z$18,$AA$14&"M / "&$Z$14&"H",$AA$15&"M / "&$Z$15&"H") -> 55M / 60H | M16: - | N16: 0 | O16: 0 | P16: 0 | Q16: 0 | R16: =IF($B16<$Z$18,$AA$14&"M / "&$Z$14&"H",ROUND($AA$14+INDEX($F$65:$F$108,$B16-2026)/12,1)&"M / "&ROUND($Z$14+INDEX($E$65:$E$108,$B16-2026)/12,1)&"H") -> 55M / 60H | S16: - | T16: 0 | U16: 0 | V16: 0 | W16: 0 | Y16: Idade média efetiva de concessão — Ī (anos) | Z16: =AH14 -> 60.735 | AA16: =AI14 -> 56.33 | AC16: =IF($Z$6='Transição 9 H e 13 M Anos'!$Z$6,"Seletores iguais nas duas abas.","ATENÇÃO: seletores distintos; comparação entre bases de Δ diferentes.") -> Seletores iguais nas duas abas. | AG16: Fonte: base Concedidos (SUIBE/INSS), espécie 41. Por ser valor pontual, não captura a dispersão das idades de concessão (premissa 9 da Nota Explicativa).
B17: 2022 | C17: ='Transição 9 H e 13 M Anos'!C17 -> 181243 | D17: ='Transição 9 H e 13 M Anos'!D17 -> 996419 | E17: =C17/D17 -> 0.18189436 | F17: ='Transição 9 H e 13 M Anos'!F17 -> 219393 | G17: ='Transição 9 H e 13 M Anos'!G17 -> 1278635 | H17: =F17/G17 -> 0.17158376 | I17: ='Transição 9 H e 13 M Anos'!I17 -> 1212 | J17: ='Transição 9 H e 13 M Anos'!J17 -> 0.059324 | K17: - | L17: =IF($B17<$Z$18,$AA$14&"M / "&$Z$14&"H",$AA$15&"M / "&$Z$15&"H") -> 55M / 60H | M17: - | N17: 0 | O17: 0 | P17: 0 | Q17: 0 | R17: =IF($B17<$Z$18,$AA$14&"M / "&$Z$14&"H",ROUND($AA$14+INDEX($F$65:$F$108,$B17-2026)/12,1)&"M / "&ROUND($Z$14+INDEX($E$65:$E$108,$B17-2026)/12,1)&"H") -> 55M / 60H | S17: - | T17: 0 | U17: 0 | V17: 0 | W17: 0 | Y17: Defasagem da concessão na regra vigente — Δ (meses) | Z17: =IF($Z$6="Idade média efetiva",ROUND(12*(Z16-Z14),0),0) -> 9 | AA17: =IF($Z$6="Idade média efetiva",ROUND(12*(AA16-AA14),0),0) -> 16
B18: 2023 | C18: ='Transição 9 H e 13 M Anos'!C18 -> 198543 | D18: ='Transição 9 H e 13 M Anos'!D18 -> 1018596 | E18: =C18/D18 -> 0.1949183 | F18: ='Transição 9 H e 13 M Anos'!F18 -> 240257 | G18: ='Transição 9 H e 13 M Anos'!G18 -> 1286407 | H18: =F18/G18 -> 0.18676593 | I18: ='Transição 9 H e 13 M Anos'!I18 -> 1320 | J18: ='Transição 9 H e 13 M Anos'!J18 -> 0.03707 | K18: - | L18: =IF($B18<$Z$18,$AA$14&"M / "&$Z$14&"H",$AA$15&"M / "&$Z$15&"H") -> 55M / 60H | M18: - | N18: 0 | O18: 0 | P18: 0 | Q18: 0 | R18: =IF($B18<$Z$18,$AA$14&"M / "&$Z$14&"H",ROUND($AA$14+INDEX($F$65:$F$108,$B18-2026)/12,1)&"M / "&ROUND($Z$14+INDEX($E$65:$E$108,$B18-2026)/12,1)&"H") -> 55M / 60H | S18: - | T18: 0 | U18: 0 | V18: 0 | W18: 0 | Y18: Início da vigência da nova regra (ano) | Z18: ='Transição 9 H e 13 M Anos'!Z18 -> 2027
B19: 2024 | C19: ='Transição 9 H e 13 M Anos'!C19 -> 180610 | D19: ='Transição 9 H e 13 M Anos'!D19 -> 1041403 | E19: =C19/D19 -> 0.1734295 | F19: ='Transição 9 H e 13 M Anos'!F19 -> 211739 | G19: ='Transição 9 H e 13 M Anos'!G19 -> 1296107 | H19: =F19/G19 -> 0.16336537 | I19: ='Transição 9 H e 13 M Anos'!I19 -> 1412 | J19: ='Transição 9 H e 13 M Anos'!J19 -> 0.0477 | K19: - | L19: =IF($B19<$Z$18,$AA$14&"M / "&$Z$14&"H",$AA$15&"M / "&$Z$15&"H") -> 55M / 60H | M19: - | N19: 0 | O19: 0 | P19: 0 | Q19: 0 | R19: =IF($B19<$Z$18,$AA$14&"M / "&$Z$14&"H",ROUND($AA$14+INDEX($F$65:$F$108,$B19-2026)/12,1)&"M / "&ROUND($Z$14+INDEX($E$65:$E$108,$B19-2026)/12,1)&"H") -> 55M / 60H | S19: - | T19: 0 | U19: 0 | V19: 0 | W19: 0 | Y19: Duração da transição — acréscimo gradual da idade mínima (anos) | Z19: 10
B20: 2025 | C20: =D20*E20 -> 176201.89 | D20: ='Transição 9 H e 13 M Anos'!D20 -> 1061714 | E20: =AVERAGE($E$15:$E$19) -> 0.16595984 | F20: =G20*H20 -> 205285.49 | G20: ='Transição 9 H e 13 M Anos'!G20 -> 1308929 | H20: =AVERAGE($H$15:$H$19) -> 0.1568347 | I20: ='Transição 9 H e 13 M Anos'!I20 -> 1518 | J20: ='Transição 9 H e 13 M Anos'!J20 -> 0.039 | K20: - | L20: =IF($B20<$Z$18,$AA$14&"M / "&$Z$14&"H",$AA$15&"M / "&$Z$15&"H") -> 55M / 60H | M20: - | N20: 0 | O20: 0 | P20: 0 | Q20: 0 | R20: =IF($B20<$Z$18,$AA$14&"M / "&$Z$14&"H",ROUND($AA$14+INDEX($F$65:$F$108,$B20-2026)/12,1)&"M / "&ROUND($Z$14+INDEX($E$65:$E$108,$B20-2026)/12,1)&"H") -> 55M / 60H | S20: - | T20: 0 | U20: 0 | V20: 0 | W20: 0 | Y20: Pagamentos por ano (12 mensalidades + 13º) | Z20: ='Transição 9 H e 13 M Anos'!Z20 -> 13
B21: 2026 | C21: =D21*E21 -> 178600.84 | D21: ='Transição 9 H e 13 M Anos'!D21 -> 1076169 | E21: =AVERAGE($E$15:$E$19) -> 0.16595984 | F21: =G21*H21 -> 207827.47 | G21: ='Transição 9 H e 13 M Anos'!G21 -> 1325137 | H21: =AVERAGE($H$15:$H$19) -> 0.1568347 | I21: ='Transição 9 H e 13 M Anos'!I21 -> 1621 | J21: ='Transição 9 H e 13 M Anos'!J21 -> 0.0376 | K21: ='Transição 9 H e 13 M Anos'!K21 -> 1 | L21: =IF($B21<$Z$18,$AA$14&"M / "&$Z$14&"H",$AA$15&"M / "&$Z$15&"H") -> 55M / 60H | M21: - | N21: 0 | O21: 0 | P21: 0 | Q21: 0 | R21: =IF($B21<$Z$18,$AA$14&"M / "&$Z$14&"H",ROUND($AA$14+INDEX($F$65:$F$108,$B21-2026)/12,1)&"M / "&ROUND($Z$14+INDEX($E$65:$E$108,$B21-2026)/12,1)&"H") -> 55M / 60H | S21: - | T21: 0 | U21: 0 | V21: 0 | W21: 0 | Y21: Observação: nesta aba, são digitados (fonte azul) a duração da transição (Z19) e o seletor do cenário (Z6), este independente do da aba "Transição 9 H e 13 M Anos"; os demais dados (idades, início da vigência, pagamentos por ano e dados de entrada) são vinculados por fórmula a essa aba, onde são digitados uma única vez. Idade mínima vigente = A₀; Ī = idade média efetiva de concessão (média 2020–2025); a idade mínima proposta equipara a rural à urbana (65 anos, homens; 62, mulheres).
B22: 2027 | C22: =D22*E22 -> 180313.88 | D22: ='Transição 9 H e 13 M Anos'!D22 -> 1086491 | E22: =AVERAGE($E$15:$E$19) -> 0.16595984 | F22: =G22*H22 -> 210859.08 | G22: ='Transição 9 H e 13 M Anos'!G22 -> 1344467 | H22: =AVERAGE($H$15:$H$19) -> 0.1568347 | I22: ='Transição 9 H e 13 M Anos'!I22 -> 1716.9632 | J22: ='Transição 9 H e 13 M Anos'!J22 -> 0.0306 | K22: =K21*(1+J22) -> 1.0306 | L22: =IF($B22<$Z$18,$AA$14&"M / "&$Z$14&"H",$AA$15&"M / "&$Z$15&"H") -> 62M / 65H | M22: =SUMPRODUCT(($B$120:$B$1751="Sem Transição")*$F$120:$F$1751*((ABS(((12*($B22-$D$120:$D$1751+1)-$E$120:$E$1751+1)-$G$120:$G$1751))-ABS(((12*($B22-$D$120:$D$1751+1)-$E$120:$E$1751+1)-$G$120:$G$1751)-12))-(ABS(((12*($B22-$D$120:$D$1751+1)-$E$120:$E$1751+1)-$S$120:$S$1751))-ABS(((12*($B22-$D$120:$D$1751+1)-$E$120:$E$1751+1)-$S$120:$S$1751)-12)))/2)*$Z$20/12 -> 97670.017 | N22: =M22*I22 -> 1.6769582e+08 | O22: =SUM(N$22:N22) -> 1.6769582e+08 | P22: =N22/$K22 -> 1.6271669e+08 | Q22: =SUM(P$22:P22) -> 1.6271669e+08 | R22: =IF($B22<$Z$18,$AA$14&"M / "&$Z$14&"H",ROUND($AA$14+INDEX($F$65:$F$108,$B22-2026)/12,1)&"M / "&ROUND($Z$14+INDEX($E$65:$E$108,$B22-2026)/12,1)&"H") -> 55,7M / 60,5H | S22: =SUMPRODUCT(($B$120:$B$1751="Com Transição")*$F$120:$F$1751*((ABS(((12*($B22-$D$120:$D$1751+1)-$E$120:$E$1751+1)-$G$120:$G$1751))-ABS(((12*($B22-$D$120:$D$1751+1)-$E$120:$E$1751+1)-$G$120:$G$1751)-12))-(ABS(((12*($B22-$D$120:$D$1751+1)-$E$120:$E$1751+1)-$S$120:$S$1751))-ABS(((12*($B22-$D$120:$D$1751+1)-$E$120:$E$1751+1)-$S$120:$S$1751)-12)))/2)*$Z$20/12 -> 0 | T22: =S22*I22 -> 0 | U22: =SUM(T$22:T22) -> 0 | V22: =T22/$K22 -> 0 | W22: =SUM(V$22:V22) -> 0 | Y22: Δ = atraso (meses) da concessão na regra vigente em relação à idade mínima vigente = 12 × (Ī − A₀), arredondado (0 se o seletor estiver em "Idade mínima vigente"). Início da vigência ≥ 2027; na transição, a idade mínima sobe a cada janeiro, em meses, até a idade proposta, ao longo da duração (Z19).
B23: 2028 | C23: =D23*E23 -> 181823.45 | D23: ='Transição 9 H e 13 M Anos'!D23 -> 1095587 | E23: =AVERAGE($E$15:$E$19) -> 0.16595984 | F23: =G23*H23 -> 213564.01 | G23: ='Transição 9 H e 13 M Anos'!G23 -> 1361714 | H23: =AVERAGE($H$15:$H$19) -> 0.1568347 | I23: ='Transição 9 H e 13 M Anos'!I23 -> 1811.9113 | J23: ='Transição 9 H e 13 M Anos'!J23 -> 0.03 | K23: =K22*(1+J23) -> 1.061518 | L23: =IF($B23<$Z$18,$AA$14&"M / "&$Z$14&"H",$AA$15&"M / "&$Z$15&"H") -> 62M / 65H | M23: =SUMPRODUCT(($B$120:$B$1751="Sem Transição")*$F$120:$F$1751*((ABS(((12*($B23-$D$120:$D$1751+1)-$E$120:$E$1751+1)-$G$120:$G$1751))-ABS(((12*($B23-$D$120:$D$1751+1)-$E$120:$E$1751+1)-$G$120:$G$1751)-12))-(ABS(((12*($B23-$D$120:$D$1751+1)-$E$120:$E$1751+1)-$S$120:$S$1751))-ABS(((12*($B23-$D$120:$D$1751+1)-$E$120:$E$1751+1)-$S$120:$S$1751)-12)))/2)*$Z$20/12 -> 2541840 | N23: =M23*I23 -> 4.6055886e+09 | O23: =SUM(N$22:N23) -> 4.7732844e+09 | P23: =N23/$K23 -> 4.3386816e+09 | Q23: =SUM(P$22:P23) -> 4.5013982e+09 | R23: =IF($B23<$Z$18,$AA$14&"M / "&$Z$14&"H",ROUND($AA$14+INDEX($F$65:$F$108,$B23-2026)/12,1)&"M / "&ROUND($Z$14+INDEX($E$65:$E$108,$B23-2026)/12,1)&"H") -> 56,4M / 61H | S23: =SUMPRODUCT(($B$120:$B$1751="Com Transição")*$F$120:$F$1751*((ABS(((12*($B23-$D$120:$D$1751+1)-$E$120:$E$1751+1)-$G$120:$G$1751))-ABS(((12*($B23-$D$120:$D$1751+1)-$E$120:$E$1751+1)-$G$120:$G$1751)-12))-(ABS(((12*($B23-$D$120:$D$1751+1)-$E$120:$E$1751+1)-$S$120:$S$1751))-ABS(((12*($B23-$D$120:$D$1751+1)-$E$120:$E$1751+1)-$S$120:$S$1751)-12)))/2)*$Z$20/12 -> 690289.89 | T23: =S23*I23 -> 1.250744e+09 | U23: =SUM(T$22:T23) -> 1.250744e+09 | V23: =T23/$K23 -> 1.1782598e+09 | W23: =SUM(V$22:V23) -> 1.1782598e+09
B24: 2029 | C24: =D24*E24 -> 183806 | D24: ='Transição 9 H e 13 M Anos'!D24 -> 1107533 | E24: =AVERAGE($E$15:$E$19) -> 0.16595984 | F24: =G24*H24 -> 216512.66 | G24: ='Transição 9 H e 13 M Anos'!G24 -> 1380515 | H24: =AVERAGE($H$15:$H$19) -> 0.1568347 | I24: ='Transição 9 H e 13 M Anos'!I24 -> 1912.8347 | J24: ='Transição 9 H e 13 M Anos'!J24 -> 0.03 | K24: =K23*(1+J24) -> 1.0933635 | L24: =IF($B24<$Z$18,$AA$14&"M / "&$Z$14&"H",$AA$15&"M / "&$Z$15&"H") -> 62M / 65H | M24: =SUMPRODUCT(($B$120:$B$1751="Sem Transição")*$F$120:$F$1751*((ABS(((12*($B24-$D$120:$D$1751+1)-$E$120:$E$1751+1)-$G$120:$G$1751))-ABS(((12*($B24-$D$120:$D$1751+1)-$E$120:$E$1751+1)-$G$120:$G$1751)-12))-(ABS(((12*($B24-$D$120:$D$1751+1)-$E$120:$E$1751+1)-$S$120:$S$1751))-ABS(((12*($B24-$D$120:$D$1751+1)-$E$120:$E$1751+1)-$S$120:$S$1751)-12)))/2)*$Z$20/12 -> 7537456.4 | N24: =M24*I24 -> 1.4417908e+10 | O24: =SUM(N$22:N24) -> 1.9191193e+10 | P24: =N24/$K24 -> 1.3186747e+10 | Q24: =SUM(P$22:P24) -> 1.7688145e+10 | R24: =IF($B24<$Z$18,$AA$14&"M / "&$Z$14&"H",ROUND($AA$14+INDEX($F$65:$F$108,$B24-2026)/12,1)&"M / "&ROUND($Z$14+INDEX($E$65:$E$108,$B24-2026)/12,1)&"H") -> 57,1M / 61,5H | S24: =SUMPRODUCT(($B$120:$B$1751="Com Transição")*$F$120:$F$1751*((ABS(((12*($B24-$D$120:$D$1751+1)-$E$120:$E$1751+1)-$G$120:$G$1751))-ABS(((12*($B24-$D$120:$D$1751+1)-$E$120:$E$1751+1)-$G$120:$G$1751)-12))-(ABS(((12*($B24-$D$120:$D$1751+1)-$E$120:$E$1751+1)-$S$120:$S$1751))-ABS(((12*($B24-$D$120:$D$1751+1)-$E$120:$E$1751+1)-$S$120:$S$1751)-12)))/2)*$Z$20/12 -> 3059295.4 | T24: =S24*I24 -> 5.8519265e+09 | U24: =SUM(T$22:T24) -> 7.1026705e+09 | V24: =T24/$K24 -> 5.3522239e+09 | W24: =SUM(V$22:V24) -> 6.5304838e+09
B25: 2030 | C25: =D25*E25 -> 186296.9 | D25: ='Transição 9 H e 13 M Anos'!D25 -> 1122542 | E25: =AVERAGE($E$15:$E$19) -> 0.16595984 | F25: =G25*H25 -> 221038.75 | G25: ='Transição 9 H e 13 M Anos'!G25 -> 1409374 | H25: =AVERAGE($H$15:$H$19) -> 0.1568347 | I25: ='Transição 9 H e 13 M Anos'!I25 -> 2019.7622 | J25: ='Transição 9 H e 13 M Anos'!J25 -> 0.03 | K25: =K24*(1+J25) -> 1.1261644 | L25: =IF($B25<$Z$18,$AA$14&"M / "&$Z$14&"H",$AA$15&"M / "&$Z$15&"H") -> 62M / 65H | M25: =SUMPRODUCT(($B$120:$B$1751="Sem Transição")*$F$120:$F$1751*((ABS(((12*($B25-$D$120:$D$1751+1)-$E$120:$E$1751+1)-$G$120:$G$1751))-ABS(((12*($B25-$D$120:$D$1751+1)-$E$120:$E$1751+1)-$G$120:$G$1751)-12))-(ABS(((12*($B25-$D$120:$D$1751+1)-$E$120:$E$1751+1)-$S$120:$S$1751))-ABS(((12*($B25-$D$120:$D$1751+1)-$E$120:$E$1751+1)-$S$120:$S$1751)-12)))/2)*$Z$20/12 -> 12706290 | N25: =M25*I25 -> 2.5663685e+10 | O25: =SUM(N$22:N25) -> 4.4854878e+10 | P25: =N25/$K25 -> 2.2788577e+10 | Q25: =SUM(P$22:P25) -> 4.0476722e+10 | R25: =IF($B25<$Z$18,$AA$14&"M / "&$Z$14&"H",ROUND($AA$14+INDEX($F$65:$F$108,$B25-2026)/12,1)&"M / "&ROUND($Z$14+INDEX($E$65:$E$108,$B25-2026)/12,1)&"H") -> 57,8M / 62H | S25: =SUMPRODUCT(($B$120:$B$1751="Com Transição")*$F$120:$F$1751*((ABS(((12*($B25-$D$120:$D$1751+1)-$E$120:$E$1751+1)-$G$120:$G$1751))-ABS(((12*($B25-$D$120:$D$1751+1)-$E$120:$E$1751+1)-$G$120:$G$1751)-12))-(ABS(((12*($B25-$D$120:$D$1751+1)-$E$120:$E$1751+1)-$S$120:$S$1751))-ABS(((12*($B25-$D$120:$D$1751+1)-$E$120:$E$1751+1)-$S$120:$S$1751)-12)))/2)*$Z$20/12 -> 6207965.4 | T25: =S25*I25 -> 1.2538614e+10 | U25: =SUM(T$22:T25) -> 1.9641284e+10 | V25: =T25/$K25 -> 1.113391e+10 | W25: =SUM(V$22:V25) -> 1.7664394e+10
